Workbook

Sheet Test Report (QC)
C1: BeeOS
A5: No. | B5: Tên chức năng | C5: TCs | D5: Đạt | E5: Không đạt | F5: Chưa xong | G5: Ghi chú
A6: 1 | B6: Đăng nhập | C6: =SUM('BeeOS - Đăng nhập'!G2) -> 17 | D6: =SUM('BeeOS - Đăng nhập'!H2) -> 17 | E6: =SUM('BeeOS - Đăng nhập'!I2) -> 0 | F6: =SUM('BeeOS - Đăng nhập'!J2) -> 0
A7: 2 | B7: Đăng xuất | C7: =SUM('BeeOS - Đăng Xuất'!G2) -> 5 | D7: =SUM('BeeOS - Đăng Xuất'!H2) -> 5 | E7: =SUM('BeeOS - Đăng Xuất'!I2) -> 0 | F7: =SUM('BeeOS - Đăng Xuất'!J2) -> 0
A8: 3 | B8: Quản lý phạm vi BH | C8: =SUM('BeeOS - Quản lý Pham vi BH'!G2) -> 21 | D8: =SUM('BeeOS - Quản lý Pham vi BH'!H2) -> 21 | E8: =SUM('BeeOS - Quản lý Pham vi BH'!I2) -> 0 | F8: =SUM('BeeOS - Quản lý Pham vi BH'!J2) -> 0
A9: 4 | B9: Quản lý mức khấu trừ | C9: =SUM('BeeOS - Quản lý Mức khấu trừ'!G2) -> 20 | D9: =SUM('BeeOS - Quản lý Mức khấu trừ'!H2) -> 20 | E9: =SUM('BeeOS - Quản lý Mức khấu trừ'!I2) -> 0 | F9: =SUM('BeeOS - Quản lý Mức khấu trừ'!J2) -> 0
A10: 5 | B10: Quản lý loại hình BH | C10: =SUM('BeeOS - Quản lý Loại hình BH'!G2) -> 26 | D10: =SUM('BeeOS - Quản lý Loại hình BH'!H2) -> 26 | E10: =SUM('BeeOS - Quản lý Loại hình BH'!I2) -> 0 | F10: =SUM('BeeOS - Quản lý Loại hình BH'!J2) -> 0
A11: 6 | B11: Quản lý ĐK bổ sung | C11: =SUM('BeeOS - Quản lý ĐK bổ sung'!G2) -> 15 | D11: =SUM('BeeOS - Quản lý ĐK bổ sung'!H2) -> 15 | E11: =SUM('BeeOS - Quản lý ĐK bổ sung'!I2) -> 0 | F11: =SUM('BeeOS - Quản lý ĐK bổ sung'!J2) -> 0
A12: 7 | B12: Quản lý Nhóm tổn thất | C12: =SUM('BeeOS - Quản lý Nhóm Tổn Thất'!G2) -> 16 | D12: =SUM('BeeOS - Quản lý Nhóm Tổn Thất'!H2) -> 16 | E12: =SUM('BeeOS - Quản lý Nhóm Tổn Thất'!I2) -> 0 | F12: =SUM('BeeOS - Quản lý Nhóm Tổn Thất'!J2) -> 0
A13: 8 | B13: Quản lý công ty bảo hiểm | C13: =SUM('BeeOS - Quản lý Công ty BH'!G2) -> 34 | D13: =SUM('BeeOS - Quản lý Công ty BH'!H2) -> 34 | E13: =SUM('BeeOS - Quản lý Công ty BH'!I2) -> 0 | F13: =SUM('BeeOS - Quản lý Công ty BH'!J2) -> 0
A14: 9 | B14: Quản lý P&L | C14: =SUM('BeeOS - Quản lý P&L'!G2) -> 30 | D14: =SUM('BeeOS - Quản lý P&L'!H2) -> 30 | E14: =SUM('BeeOS - Quản lý P&L'!I2) -> 0 | F14: =SUM('BeeOS - Quản lý P&L'!J2) -> 0
A15: 10 | B15: Quản lý địa điểm | C15: =SUM('BeeOS - Quản lý địa điểm'!G2) -> 23 | D15: =SUM('BeeOS - Quản lý địa điểm'!H2) -> 23 | E15: =SUM('BeeOS - Quản lý địa điểm'!I2) -> 0 | F15: =SUM('BeeOS - Quản lý địa điểm'!J2) -> 0
A16: 11 | B16: Tài khoản | C16: =SUM('BeeOS - Tài khoản'!G2) -> 24 | D16: =SUM('BeeOS - Tài khoản'!H2) -> 24 | E16: =SUM('BeeOS - Tài khoản'!I2) -> 0 | F16: =SUM('BeeOS - Tài khoản'!J2) -> 0
A17: 12 | B17: Cài đặt chế độ bảo trì | C17: =SUM('BeeOS - Cài đặt chế độ bảo trì'!G2) -> 8 | D17: =SUM('BeeOS - Cài đặt chế độ bảo trì'!H2) -> 8 | E17: =SUM('BeeOS - Cài đặt chế độ bảo trì'!I2) -> 0 | F17: =SUM('BeeOS - Cài đặt chế độ bảo trì'!J2) -> 0
A18: 13 | B18: Cài đặt thông báo | C18: =SUM('BeeOS - Cài đặt thông báo'!G2) -> 8 | D18: =SUM('BeeOS - Cài đặt thông báo'!H2) -> 8 | E18: =SUM('BeeOS - Cài đặt thông báo'!I2) -> 0 | F18: =SUM('BeeOS - Cài đặt thông báo'!J2) -> 0
A19: 14 | B19: Quản lý HĐBH(B1) | C19: =SUM('BeeOS - Quản lý HĐBH(B1)'!G2) -> 16 | D19: =SUM('BeeOS - Quản lý HĐBH(B1)'!H2) -> 16 | E19: =SUM('BeeOS - Quản lý HĐBH(B1)'!I2) -> 0 | F19: =SUM('BeeOS - Quản lý HĐBH(B1)'!J2) -> 0
A20: 15 | B20: Quản lý HĐBH(B2) | C20: =SUM('BeeOS - Quản lý HĐBH(B2)'!G2) -> 10 | D20: =SUM('BeeOS - Quản lý HĐBH(B2)'!H2) -> 10 | E20: =SUM('BeeOS - Quản lý HĐBH(B2)'!I2) -> 0 | F20: =SUM('BeeOS - Quản lý HĐBH(B2)'!J2) -> 0
A21: 16 | B21: Quản lý HĐBH(B3) | C21: =SUM('BeeOS - Quản lý HĐBH(B3)'!G2) -> 10 | D21: =SUM('BeeOS - Quản lý HĐBH(B3)'!H2) -> 10 | E21: =SUM('BeeOS - Quản lý HĐBH(B3)'!I2) -> 0 | F21: =SUM('BeeOS - Quản lý HĐBH(B3)'!J2) -> 0
A22: 17 | B22: Quản lý HĐBH(B4) | C22: =SUM('BeeOS - Quản lý HĐBH(B4)'!G2) -> 20 | D22: =SUM('BeeOS - Quản lý HĐBH(B4)'!H2) -> 20 | E22: =SUM('BeeOS - Quản lý HĐBH(B4)'!I2) -> 0 | F22: =SUM('BeeOS - Quản lý HĐBH(B4)'!J2) -> 0
A23: 18 | B23: KT Bản chào phí | C23: =SUM('BeeOS - KT Bản chào phí'!G2) -> 16 | D23: =SUM('BeeOS - KT Bản chào phí'!H2) -> 16 | E23: =SUM('BeeOS - KT Bản chào phí'!I2) -> 0 | F23: =SUM('BeeOS - KT Bản chào phí'!J2) -> 0
A24: 19 | B24: Tạo phụ lục HĐ (B1) | C24: =SUM('BeeOS - Tạo phụ lục HĐBH(B1)'!G2) -> 22 | D24: =SUM('BeeOS - Tạo phụ lục HĐBH(B1)'!H2) -> 22 | E24: =SUM('BeeOS - Tạo phụ lục HĐBH(B1)'!I2) -> 0 | F24: =SUM('BeeOS - Tạo phụ lục HĐBH(B1)'!J2) -> 0
A25: 20 | B25: Tạo phụ lục HĐ (B2) | C25: =SUM('BeeOS - Tạo Phụ lục HĐ(B2)'!G2) -> 19 | D25: =SUM('BeeOS - Tạo Phụ lục HĐ(B2)'!H2) -> 19 | E25: =SUM('BeeOS - Tạo Phụ lục HĐ(B2)'!I2) -> 0 | F25: =SUM('BeeOS - Tạo Phụ lục HĐ(B2)'!J2) -> 0
A26: 21 | B26: Trang vận hành cấp đơn | C26: =SUM('BeeOS -Trang vận hành cấp đơn'!G2) -> 18 | D26: =SUM('BeeOS -Trang vận hành cấp đơn'!H2) -> 18 | E26: =SUM('BeeOS -Trang vận hành cấp đơn'!I2) -> 0 | F26: =SUM('BeeOS -Trang vận hành cấp đơn'!J2) -> 0
A27: 22 | B27: Trang list HĐBH | C27: =SUM('BeeOS - Trang List HĐBH'!G2) -> 21 | D27: =SUM('BeeOS - Trang List HĐBH'!H2) -> 21 | E27: =SUM('BeeOS - Trang List HĐBH'!I2) -> 0 | F27: =SUM('BeeOS - Trang List HĐBH'!J2) -> 0
A28: 23 | B28: Chi tiết HĐ (Nháp) | C28: =SUM('BeeOS - ChiTiết HĐ (Nháp)'!G2) -> 9 | D28: =SUM('BeeOS - ChiTiết HĐ (Nháp)'!H2) -> 9 | E28: =SUM('BeeOS - ChiTiết HĐ (Nháp)'!I2) -> 0 | F28: =SUM('BeeOS - ChiTiết HĐ (Nháp)'!J2) -> 0
A29: 24 | B29: Chi tiết HĐ (Chờ duyệt CT) | C29: =SUM('BeeO-ChiTiết HĐ (Chờ Duyệt CT)'!G2) -> 12 | D29: =SUM('BeeO-ChiTiết HĐ (Chờ Duyệt CT)'!H2) -> 12 | E29: =SUM('BeeO-ChiTiết HĐ (Chờ Duyệt CT)'!I2) -> 0 | F29: =SUM('BeeO-ChiTiết HĐ (Chờ Duyệt CT)'!J2) -> 0
A30: 25 | B30: Chi tiết HĐ (Chỉnh sửa ĐX) | C30: =SUM('BeeOS-ChiTiết HĐ (Chỉnh sửa ĐX)'!G2) -> 19 | D30: =SUM('BeeOS-ChiTiết HĐ (Chỉnh sửa ĐX)'!H2) -> 19 | E30: =SUM('BeeOS-ChiTiết HĐ (Chỉnh sửa ĐX)'!I2) -> 0 | F30: =SUM('BeeOS-ChiTiết HĐ (Chỉnh sửa ĐX)'!J2) -> 0
A31: 26 | B31: Chi tiết HĐ (Đã duyệt CT) | C31: =SUM('BeeOS-ChiTiết HĐ (Đã Duyệt CT)'!G2) -> 14 | D31: =SUM('BeeOS-ChiTiết HĐ (Đã Duyệt CT)'!H2) -> 14 | E31: =SUM('BeeOS-ChiTiết HĐ (Đã Duyệt CT)'!I2) -> 0 | F31: =SUM('BeeOS-ChiTiết HĐ (Đã Duyệt CT)'!J2) -> 0
A32: 27 | B32: Chi tiết HĐ (Chờ duyệt NL) | C32: =SUM('BeeO-ChiTiết HĐ (Chờ Duyệt NL)'!G2) -> 14 | D32: =SUM('BeeO-ChiTiết HĐ (Chờ Duyệt NL)'!H2) -> 14 | E32: =SUM('BeeO-ChiTiết HĐ (Chờ Duyệt NL)'!I2) -> 0 | F32: =SUM('BeeO-ChiTiết HĐ (Chờ Duyệt NL)'!J2) -> 0
A33: 28 | B33: Chi tiết HĐ (Chỉnh sửa NL) | C33: =SUM('BeeOS-ChiTiết HĐ (Chỉnh sửa NL)'!G2) -> 19 | D33: =SUM('BeeOS-ChiTiết HĐ (Chỉnh sửa NL)'!H2) -> 19 | E33: =SUM('BeeOS-ChiTiết HĐ (Chỉnh sửa NL)'!I2) -> 0 | F33: =SUM('BeeOS-ChiTiết HĐ (Chỉnh sửa NL)'!J2) -> 0
A34: 29 | B34: Chi tiết HĐ (Đã duyệt NL) | C34: =SUM('BeeOS-ChiTiết HĐ (Đã Duyệt NL)'!G2) -> 15 | D34: =SUM('BeeOS-ChiTiết HĐ (Đã Duyệt NL)'!H2) -> 15 | E34: =SUM('BeeOS-ChiTiết HĐ (Đã Duyệt NL)'!I2) -> 0 | F34: =SUM('BeeOS-ChiTiết HĐ (Đã Duyệt NL)'!J2) -> 0
A35: 30 | B35: Chi tiết HĐ (TBH đã duyệt) | C35: =SUM('BeeOS-ChiTiết HĐ (TBH Đã Duyệt)'!G2) -> 15 | D35: =SUM('BeeOS-ChiTiết HĐ (TBH Đã Duyệt)'!H2) -> 15 | E35: =SUM('BeeOS-ChiTiết HĐ (TBH Đã Duyệt)'!I2) -> 0 | F35: =SUM('BeeOS-ChiTiết HĐ (TBH Đã Duyệt)'!J2) -> 0
A36: 31 | B36: Chi tiết HĐ (Đã lưu BCHĐ) | C36: =SUM('BeeOS-ChiTiết HĐ (Đã lưu BCHĐ)'!G2) -> 18 | D36: =SUM('BeeOS-ChiTiết HĐ (Đã lưu BCHĐ)'!H2) -> 18 | E36: =SUM('BeeOS-ChiTiết HĐ (Đã lưu BCHĐ)'!I2) -> 0 | F36: =SUM('BeeOS-ChiTiết HĐ (Đã lưu BCHĐ)'!J2) -> 0
A37: 32 | B37: Chi tiết HĐ (Phụ lục) | C37: =SUM('BeeOS-ChiTiết HĐ (Phụ Lục)'!G2) -> 18 | D37: =SUM('BeeOS-ChiTiết HĐ (Phụ Lục)'!H2) -> 18 | E37: =SUM('BeeOS-ChiTiết HĐ (Phụ Lục)'!I2) -> 0 | F37: =SUM('BeeOS-ChiTiết HĐ (Phụ Lục)'!J2) -> 0
A38: 33 | B38: Leader trang list phê duyệt | C38: =SUM('BeeOS - Leader list phê duyệt'!G2) -> 15 | D38: =SUM('BeeOS - Leader list phê duyệt'!H2) -> 15 | E38: =SUM('BeeOS - Leader list phê duyệt'!I2) -> 0 | F38: =SUM('BeeOS - Leader list phê duyệt'!J2) -> 0
A39: 34 | B39: Phê duyệt CT (B1) | C39: =SUM('BeeOS - Phê Duyệt CT (B1)'!G2) -> 20 | D39: =SUM('BeeOS - Phê Duyệt CT (B1)'!H2) -> 20 | E39: =SUM('BeeOS - Phê Duyệt CT (B1)'!I2) -> 0 | F39: =SUM('BeeOS - Phê Duyệt CT (B1)'!J2) -> 0
A40: 35 | B40: Phê duyệt NL (B2) | C40: =SUM('BeeOS - Phê Duyệt NL (B2)'!F2) -> 23 | D40: =SUM('BeeOS - Phê Duyệt NL (B2)'!G2) -> 23 | E40: =SUM('BeeOS - Phê Duyệt NL (B2)'!H2) -> 0 | F40: =SUM('BeeOS - Phê Duyệt NL (B2)'!I2) -> 0
A41: 36 | B41: Phê duyệt Phụ Lục | C41: =SUM('BeeOS - Phê Duyệt Phụ Lục'!F2) -> 15 | D41: =SUM('BeeOS - Phê Duyệt Phụ Lục'!G2) -> 15 | E41: =SUM('BeeOS - Phê Duyệt Phụ Lục'!H2) -> 0 | F41: =SUM('BeeOS - Phê Duyệt Phụ Lục'!I2) -> 0
A42: 37 | B42: Leader Trang đã duyệt | C42: =SUM('BeeOS - Leader Trang Đã duyệt'!F2) -> 15 | D42: =SUM('BeeOS - Leader Trang Đã duyệt'!G2) -> 15 | E42: =SUM('BeeOS - Leader Trang Đã duyệt'!H2) -> 0 | F42: =SUM('BeeOS - Leader Trang Đã duyệt'!I2) -> 0
A43: 38 | B43: Email và Tin nhắn Zalo | C43: =('BeeOS - Email và Tin nhắn Zalo'!F2) -> 27 | D43: =('BeeOS - Email và Tin nhắn Zalo'!G2) -> 27 | E43: =('BeeOS - Email và Tin nhắn Zalo'!H2) -> 0 | F43: =('BeeOS - Email và Tin nhắn Zalo'!I2) -> 0
...

Sheet BeeOS - Đăng nhập
B1: Tên chức năng | D1: Đăng nhập & Quên mật khẩu | G1: Tổng TCs | H1: Đạt | I1: Không đạt | J1: Chưa xong
B2: Người tạo | D2: Levi | G2: =COUNTIF(A6:A68,"TC-??") -> 17 | H2: =COUNTIF(I4:I925,"Đạt") -> 17 | I2: =COUNTIF(I4:I925,"Không Đạt") -> 0 | J2: =COUNTIF(G4:G925,"Chưa Xong") -> 0
B3: Ngày Tạo | D3: 45980 | G3: =SUM(H3+I3+J3) -> 1 | H3: =H2/G2 -> 1 | I3: =I2/G2 -> 0 | J3: =J2/G2 -> 0
A5: ID | B5: Mô tả User Story | C5: Chức năng chính | D5: Chức năng con | E5: Điều kiện tiên quyết | F5: Mô tả | G5: Các bước thực hiện | H5: Kết quả mong đợi | I5: Kết quả thực tế
A6: TC-01 | B6: Là Admin, tôi muốn đăng nhập bằng email và mật khẩu hợp lệ để vào trang chính | C6: Đăng nhập | D6: Đăng nhập thủ công | E6: Admin đã có tài khoản active | F6: Kiểm tra đăng nhập thành công với thông tin hợp lệ | G6: 1. Mở trang đăng nhập 2. Nhập email admin[at]example.com 3. Nhập mật khẩu đúng 4. Nhấn Đăng nhập | H6: Hệ thống đăng nhập thành công; Chuyển đến trang chính với vai trò Admin | I6: Đạt
A7: TC-02 | B7: Là Admin, tôi muốn biết khi nhập sai mật khẩu để nhập lại | C7: Đăng nhập | D7: Đăng nhập thủ công | E7: Admin đã có tài khoản active | F7: Kiểm tra đăng nhập với mật khẩu sai | G7: 1. Nhập email admin[at]example.com 2. Nhập sai mật khẩu 3. Nhấn Đăng nhập | H7: Hệ thống không đăng nhập; Hiển thị thông báo sai mật khẩu | I7: Đạt
A8: TC-03 | B8: Là Admin, tôi muốn biết khi nhập sai định dạng email | C8: Đăng nhập | D8: Đăng nhập thủ công | E8: Có màn hình đăng nhập | F8: Kiểm tra nhập email sai định dạng | G8: 1. Nhập email admin.example.com 2. Nhập mật khẩu bất kỳ 3. Nhấn Đăng nhập | H8: Hệ thống không đăng nhập; Hiển thị lỗi định dạng email | I8: Đạt
A9: TC-04 | B9: Là Admin, tôi muốn hệ thống nhắc nhập email khi để trống | C9: Đăng nhập | D9: Đăng nhập thủ công | E9: Có màn hình đăng nhập | F9: Kiểm tra để trống email | G9: 1. Để trống email 2. Nhập mật khẩu bất kỳ 3. Nhấn Đăng nhập | H9: Hệ thống hiển thị thông báo bắt buộc nhập email | I9: Đạt
A10: TC-05 | B10: Là Admin, tôi muốn hệ thống nhắc nhập mật khẩu khi để trống | C10: Đăng nhập | D10: Đăng nhập thủ công | E10: Có màn hình đăng nhập | F10: Kiểm tra để trống mật khẩu | G10: 1. Nhập admin[at]example.com 2. Để trống mật khẩu 3. Nhấn Đăng nhập | H10: Hệ thống hiển thị yêu cầu nhập mật khẩu | I10: Đạt
A11: TC-07 | B11: Là Admin, tôi muốn xem thông báo nếu bỏ trống cả email và mật khẩu | C11: Đăng nhập | D11: Đăng nhập thủ công | E11: Có màn hình đăng nhập | F11: Kiểm tra bỏ trống cả 2 trường | G11: 1. Để trống email và mật khẩu 2. Nhấn Đăng nhập | H11: Hệ thống hiển thị lỗi yêu cầu nhập email và mật khẩu | I11: Đạt
A12: TC-08 | B12: Là Admin, tôi muốn hệ thống giữ phiên đăng nhập nếu refresh trang | C12: Đăng nhập | D12: Quản lý phiên | E12: Admin đã đăng nhập thành công | F12: Kiểm tra session sau khi refresh | G12: 1. Đăng nhập thành công 2. Refresh trình duyệt | H12: Hệ thống vẫn giữ trạng thái đăng nhập; Hiển thị trang chính | I12: Đạt
A13: TC-09 | B13: Là Admin, tôi muốn được yêu cầu đổi mật khẩu nếu quên | C13: Quên mật khẩu | D13: Gửi yêu cầu reset | E13: Admin quên mật khẩu | F13: Kiểm tra gửi yêu cầu quên mật khẩu | G13: 1. Nhấn Forgot Password 2. Nhập admin[at]example.com 3. Nhấn Gửi yêu cầu | H13: Hệ thống gửi email đặt lại mật khẩu; Hiển thị thông báo gửi email thành công | I13: Đạt
A14: TC-10 | B14: Là Underwriter, tôi muốn đăng nhập thành công bằng email và mật khẩu | C14: Đăng nhập | D14: Đăng nhập thủ công | E14: Underwriter có tài khoản active | F14: Đăng nhập Underwriter hợp lệ | G14: 1. Nhập email uw[at]example.com 2. Nhập mật khẩu đúng 3. Nhấn Đăng nhập | H14: Hệ thống đăng nhập thành công; Chuyển đến trang chính với vai trò Underwriter | I14: Đạt
A15: TC-11 | B15: Là Claim Officer, tôi muốn đăng nhập thành công bằng email và mật khẩu | C15: Đăng nhập | D15: Đăng nhập thủ công | E15: Claim Officer có tài khoản active | F15: Đăng nhập Claim Officer hợp lệ | G15: 1. Nhập email claim[at]example.com 2. Nhập mật khẩu đúng 3. Nhấn Đăng nhập | H15: Hệ thống đăng nhập thành công; Chuyển đến trang chính với vai trò Claim Officer | I15: Đạt
A16: TC-12 | B16: Là Underwriter/Claim Officer, tôi muốn đăng nhập bằng Gmail liên kết | C16: Đăng nhập | D16: Đăng nhập bằng Gmail | E16: Tài khoản đã liên kết Google | F16: Kiểm tra đăng nhập bằng Google | G16: 1. Nhấn Đăng nhập bằng Google 2. Chọn tài khoản Google đã liên kết | H16: Hệ thống xác thực Google thành công; Chuyển đến trang chính với vai trò tương ứng | I16: Đạt
... A22: TC-18 | B22: Là người dùng, tôi muốn quay lại màn hình đăng nhập nếu hủy đăng nhập bằng Google | C22: Đăng nhập bằng Gmail | D22: Đăng nhập Google | E22: Người dùng đang đăng nhập bằng Google | F22: Kiểm tra hủy trong popup Google | G22: 1. Nhấn Đăng nhập bằng Google 2. Chọn Hủy tại popup | H22: Hệ thống không tạo phiên đăng nhập; Quay lại màn hình đăng nhập ban đầu | I22: Đạt

Sheet BeeOS - Đăng Xuất
B1: Tên chức năng | D1: Đăng Xuất | G1: Tổng TCs | H1: Đạt | I1: Không đạt | J1: Chưa xong
B2: Người tạo | D2: Levi | G2: =COUNTIF(A5:A44,"TC-??") -> 5 | H2: =COUNTIF(I4:I901,"Đạt") -> 5 | I2: =COUNTIF(I4:I901,"Không Đạt") -> 0 | J2: =COUNTIF(G4:G901,"Chưa Xong") -> 0
B3: Ngày Tạo | D3: 45986 | G3: =SUM(H3+I3+J3) -> 1 | H3: =H2/G2 -> 1 | I3: =I2/G2 -> 0 | J3: =J2/G2 -> 0
A5: ID | B5: Mô tả User Story | C5: Chức năng chính | D5: Chức năng con | E5: Điều kiện tiên quyết | F5: Mô tả | G5: Các bước thực hiện | H5: Kết quả mong đợi | I5: Kết quả thực tế
A6: TC-01 | B6: Hiển thị thông tin user và nút Logout | C6: Đăng Xuất | D6: Hiển thị user + nút logout | E6: Người dùng đã đăng nhập | F6: Góc trái dưới hiển thị avatar, tên, chức danh và icon logout | G6: 1. Đăng nhập bằng account hợp lệ; 2. Quan sát góc trái dưới màn hình | H6: Hiển thị avatar đúng; hiển thị tên và chức danh đúng; hiển thị icon logout (mũi tên) | I6: Đạt
A7: TC-02 | B7: Mở dialog xác nhận khi click logout | C7: Đăng Xuất | D7: Dialog xác nhận logout | E7: User đang đăng nhập và nhấn icon logout | F7: Khi người dùng nhấn icon logout phải hiện dialog xác nhận | G7: 1. Nhấn icon logout ở góc trái dưới; 2. Quan sát dialog hiển thị | H7: Hiển thị dialog xác nhận với 2 tùy chọn: Xác nhận (Logout) và Hủy | I7: Đạt
A8: TC-03 | B8: Logout thành công sau khi xác nhận | C8: Đăng Xuất | D8: Xoá session / redirect về login | E8: Dialog xác nhận hiển thị và user chọn xác nhận | F8: Sau xác nhận, user được đăng xuất và về trang Login | G8: 1. Nhấn icon logout; 2. Nhấn nút Xác nhận trong dialog | H8: Người dùng được redirect về màn hình Login; session/token bị xoá; truy cập trang nội bộ trả về yêu cầu đăng nhập | I8: Đạt
A9: TC-04 | B9: Kiểm tra multiple tabs sau logout (session sync) | C9: Đăng Xuất | D9: Đồng bộ logout giữa tab | E9: User đăng nhập trên nhiều tab | F9: Logout trên 1 tab phải khiến các tab khác redirect về Login | G9: 1. Mở 2 tab cùng account; 2. Logout ở tab A; 3. Quan sát tab B | H9: Tab B tự động redirect về Login hoặc hiển thị thông báo phiên đã bị đăng xuất | I9: Đạt
A10: TC-05 | B10: Accessibility / keyboard support cho logout | C10: Đăng Xuất | D10: Keyboard & Screen reader | E10: User có nhu cầu hỗ trợ a11y | F10: Nút logout và dialog phải có keyboard focus & ARIA labels | G10: 1. Dùng phím Tab đến icon logout; 2. Nhấn Enter; 3. Dùng phím di chuyển trong dialog | H10: Icon có thể focus bằng keyboard; dialog có tiêu đề rõ ràng; có nút xác nhận/hủy có thể thao tác bằng keyboard; screen reader đọc được nội dung | I10: Đạt

Sheet BeeOS - Quản lý Pham vi BH
B1: Tên chức năng | D1: Quản lý Pham vi Bảo Hiểm | G1: Tổng TCs | H1: Đạt | I1: Không đạt | J1: Chưa xong
B2: Người tạo | D2: Levi | G2: =COUNTIF(A6:A76,"TC-??") -> 21 | H2: =COUNTIF(I4:I933,"Đạt") -> 21 | I2: =COUNTIF(G4:G933,"Không Đạt") -> 0 | J2: =COUNTIF(G4:G933,"Chưa Xong") -> 0
B3: Ngày Tạo | D3: 45981 | G3: =SUM(H3+I3+J3) -> 1 | H3: =H2/G2 -> 1 | I3: =I2/G2 -> 0 | J3: =J2/G2 -> 0
A5: ID | B5: User Story | C5: Chức năng chính | D5: Chức năng con | E5: Điều kiện tiên quyết | F5: Mô tả | G5: Các bước thực hiện | H5: Kết quả mong đợi | I5: Kết quả thực tế
A6: TC-01 | B6: Là Admin, tôi muốn truy cập màn hình Quản lý Phạm vi Bảo hiểm | C6: Quản lý Phạm vi Bảo hiểm | D6: Truy cập màn hình | E6: Admin đã đăng nhập hệ thống | F6: Kiểm tra khả năng truy cập màn hình danh sách Phạm vi BH | G6: 1. Đăng nhập với quyền Admin;2. Chọn menu Quản lý chung;3. Chọn Phạm vi bảo hiểm | H6: Hệ thống hiển thị màn hình Quản lý Phạm vi Bảo hiểm | I6: Đạt
A7: TC-02 | B7: Là Admin, tôi muốn xem danh sách Phạm vi BH | C7: Quản lý Phạm vi Bảo hiểm | D7: . | E7: Đang ở màn hình Quản lý Phạm vi BH | F7: Hiển thị danh sách phạm vi bảo hiểm | G7: 1. Truy cập màn hình danh sách | H7: Hiển thị danh sách gồm: Tên phạm vi BH, Cơ sở bồi thường, nút Sửa/Xóa | I7: Đạt
A8: TC-03 | B8: Là Admin, tôi muốn tìm kiếm Phạm vi BH | C8: Quản lý Phạm vi Bảo hiểm | D8: Tìm kiếm | E8: Có dữ liệu phạm vi BH | F8: Tìm kiếm theo tên phạm vi bảo hiểm | G8: 1. Nhập từ khóa vào ô Tìm kiếm;2. Quan sát danh sách | H8: Chỉ hiển thị các bản ghi phù hợp với từ khóa | I8: Đạt
A9: TC-04 | B9: Là Admin, tôi muốn sắp xếp theo thứ tự tăng dần cho cột Tên phạm vi BH | C9: Quản lý Loại hình BH | D9: Xem danh sách | E9: Đang ở màn hình danh sách | F9: Sắp xếp tăng dần cho cột Tên viết tắt | G9: 1. Sắp xếp cột Tên phạm vi BH tăng dần | H9: 1. Hiển thị đúng tên phạm vi BH tăng dần | I9: Đạt
A10: TC-05 | B10: Là Admin, tôi muốn sắp xếp theo thứ tự giảm dần cho cột Tên phạm vi BH | C10: Quản lý Loại hình BH | D10: Xem danh sách | E10: Đang ở màn hình danh sách | F10: Sắp xếp giảm dần cho cột Tên đầy đủ | G10: 1. Sắp xếp cột Tên phạm vi BH giảm dần | H10: 1. Hiển thị đúng tên phạm vi BH giảm dần | I10: Đạt
A11: TC-06 | B11: Là Admin, tôi muốn phân trang danh sách | C11: Quản lý Phạm vi Bảo hiểm | D11: Phân trang | E11: Có nhiều hơn 1 trang dữ liệu | F11: Kiểm tra điều hướng trang | G11: 1. Nhấn Trang tiếp;2. Nhấn Trang trước;3. Chọn số trang | H11: Dữ liệu hiển thị đúng theo trang được chọn | I11: Đạt
A12: TC-07 | B12: Là Admin, tôi muốn mở màn hình tạo mới Phạm vi BH | C12: Quản lý Phạm vi Bảo hiểm | D12: Mở form tạo mới | E12: Đang ở màn hình danh sách | F12: Điều hướng sang màn hình tạo mới | G12: 1. Nhấn + Thêm Phạm vi Bảo hiểm | H12: Hệ thống mở màn hình Tạo phạm vi bảo hiểm | I12: Đạt
A13: TC-08 | B13: Là Admin, tôi muốn tạo Phạm vi BH với dữ liệu hợp lệ | C13: Quản lý Phạm vi Bảo hiểm | D13: Tạo mới | E13: Đang ở màn hình Tạo phạm vi BH | F13: Tạo mới phạm vi bảo hiểm thành công | G13: 1. Nhập Tên phạm vi BH;2. Nhập Cơ sở bồi thường;3. Chọn Trạng thái;4. Nhấn Tạo phạm vi bảo hiểm | H13: Phạm vi BH được tạo thành công và hiển thị trong danh sách | I13: Đạt
A14: TC-09 | B14: Là Admin, tôi không muốn tạo khi thiếu Tên phạm vi BH | C14: Quản lý Phạm vi Bảo hiểm | D14: Validate dữ liệu | E14: Đang ở màn hình Tạo mới | F14: Kiểm tra validate trường bắt buộc | G14: 1. Để trống Tên phạm vi BH;2. Nhấn Tạo phạm vi bảo hiểm | H14: Hiển thị thông báo lỗi yêu cầu nhập Tên phạm vi BH | I14: Đạt
A15: TC-10 | B15: Là Admin, tôi không muốn tạo khi thiếu Cơ sở bồi thường | C15: Quản lý Phạm vi Bảo hiểm | D15: Validate dữ liệu | E15: Đang ở màn hình Tạo mới | F15: Kiểm tra validate trường bắt buộc | G15: 1. Để trống Cơ sở bồi thường;2. Nhấn Tạo phạm vi bảo hiểm | H15: Hiển thị thông báo lỗi yêu cầu nhập Cơ sở bồi thường | I15: Đạt
A16: TC-11 | B16: Là Admin, tôi muốn thêm Mức khấu trừ | C16: Quản lý Phạm vi Bảo hiểm | D16: Thêm mức khấu trừ | E16: Đang ở màn hình Tạo/Sửa | F16: Thêm danh sách mức khấu trừ | G16: 1. Nhấn + Thêm mức khấu trừ;2. Nhập thông tin mức khấu trừ | H16: Mức khấu trừ được thêm vào danh sách | I16: Đạt
... A26: TC-21 | B26: Là Admin, tôi muốn quay lại danh sách từ màn hình Tạo/Sửa | C26: Quản lý Phạm vi Bảo hiểm | D26: Quay lại | E26: Đang ở màn hình Tạo/Sửa | F26: Điều hướng | G26: 1. Nhấn Quay lại | H26: Quay về màn hình danh sách | I26: Đạt

Sheet BeeOS - Quản lý Mức khấu trừ
B1: Tên chức năng | D1: Quản lý Mức khấu trừ | G1: Tổng TCs | H1: Đạt | I1: Không đạt | J1: Chưa xong
B2: Người tạo | D2: Levi | G2: =COUNTIF(A6:A75,"TC-??") -> 20 | H2: =COUNTIF(I4:I932,"Đạt") -> 20 | I2: =COUNTIF(I4:I932,"Không Đạt") -> 0 | J2: =COUNTIF(G4:G932,"Chưa Xong") -> 0
B3: Ngày Tạo | D3: 45981 | G3: =SUM(H3+I3+J3) -> 1 | H3: =H2/G2 -> 1 | I3: =I2/G2 -> 0 | J3: =J2/G2 -> 0
A5: ID | B5: User Story | C5: Chức năng chính | D5: Chức năng con | E5: Điều kiện tiên quyết | F5: Mô tả | G5: Các bước thực hiện | H5: Kết quả mong đợi | I5: Kết quả thực tế
A6: TC-01 | B6: Là Admin, tôi muốn truy cập màn hình Quản lý Mức khấu trừ | C6: Quản lý Mức khấu trừ | D6: Truy cập màn hình | E6: Admin đã đăng nhập | F6: Kiểm tra truy cập màn hình danh sách | G6: 1. Đăng nhập bằng tài khoản Admin;2. Chọn Quản lý chung;3. Chọn Mức khấu trừ | H6: Hệ thống hiển thị màn hình Quản lý Mức khấu trừ | I6: Đạt
A7: TC-02 | B7: Là Admin, tôi muốn xem danh sách Mức khấu trừ | C7: Quản lý Mức khấu trừ | D7: Xem danh sách | E7: Đang ở màn hình Quản lý | F7: Hiển thị danh sách mức khấu trừ | G7: 1. Truy cập màn hình danh sách | H7: Hiển thị các cột: Tên mức khấu trừ, Mức khấu trừ , nút Sửa/Xóa | I7: Đạt
A8: TC-03 | B8: Là Admin, tôi muốn tìm kiếm Mức khấu trừ | C8: Quản lý Mức khấu trừ | D8: Tìm kiếm | E8: Có dữ liệu mức khấu trừ | F8: Tìm kiếm theo tên mức khấu trừ | G8: 1. Nhập từ khóa vào ô Tìm kiếm | H8: Danh sách hiển thị đúng các bản ghi phù hợp | I8: Đạt
A9: TC-04 | B9: Là Admin, tôi muốn phân trang danh sách | C9: Quản lý Mức khấu trừ | D9: Phân trang | E9: Có nhiều trang dữ liệu | F9: Điều hướng giữa các trang | G9: 1. Nhấn Trang tiếp / Trang trước;2. Chọn số trang | H9: Dữ liệu hiển thị đúng theo trang | I9: Đạt
A10: TC-05 | B10: Là Admin, tôi muốn sắp xếp theo thứ tự tăng dần cho cột Tên mức khấu trừ | C10: Quản lý Mức khấu trừ | D10: Xem danh sách | E10: Đang ở màn hình danh sách | F10: Sắp xếp tăng dần cho cột tên Tên mức khấu trừ | G10: 1. Sắp xếp cột Tên mức khấu trừ | H10: 1. Hiển thị đúng Tên mức khấu trừ | I10: Đạt
A11: TC-06 | B11: Là Admin, tôi muốn sắp xếp theo thứ tự giảm dần cho cột Tên mức khấu trừ | C11: Quản lý Mức khấu trừ | D11: Xem danh sách | E11: Đang ở màn hình danh sách | F11: Sắp xếp giảm dần cho cột Tên mức khấu trừ | G11: 1. Sắp xếp cột Tên mức khấu trừ | H11: 1. Hiển thị đúng Tên mức khấu trừ | I11: Đạt
A12: TC-07 | B12: Là Admin, tôi muốn mở màn hình tạo Mức khấu trừ | C12: Quản lý Mức khấu trừ | D12: Mở form tạo mới | E12: Đang ở màn hình danh sách | F12: Điều hướng sang màn hình tạo | G12: 1. Nhấn + Thêm mức khấu trừ | H12: Mở màn hình Tạo Mức khấu trừ | I12: Đạt
A13: TC-08 | B13: Là Admin, tôi muốn tạo Mức khấu trừ hợp lệ | C13: Quản lý Mức khấu trừ | D13: Tạo mới | E13: Đang ở màn hình Tạo | F13: Tạo mới thành công | G13: 1. Nhập Tên mức khấu trừ;2. Nhập Mức khấu trừ 3. Nhấn Tạo mức khấu trừ | H13: Mức khấu trừ được tạo thành công và hiển thị trong danh sách | I13: Đạt
A14: TC-09 | B14: Là Admin, tôi không thể tạo khi thiếu Tên mức khấu trừ | C14: Quản lý Mức khấu trừ | D14: Validate dữ liệu | E14: Đang ở màn hình Tạo | F14: Kiểm tra trường bắt buộc | G14: 1. Để trống Tên mức khấu trừ;2. Nhấn Tạo mức khấu trừ | H14: Hiển thị thông báo yêu cầu nhập Tên mức khấu trừ | I14: Đạt
A15: TC-10 | B15: Là Admin tôi không thể tạo khi nhập tên mức khấu trừ đã tồn tại | C15: Quản lý Mức khấu trừ | D15: Validate dữ liệu | E15: Đang ở màn hình Tạo | F15: Kiểm tra trường bắt buộc | G15: 1. Nhập tên mức khấu trừ đã tồn tại 2. Nhấn "Tạo mức khấu trừ" | H15: Hiển thị thông báo Tên mức khấu trừ đã tồn tại | I15: Đạt
A16: TC-11 | B16: Là Admin, tôi muốn hủy thao tác tạo mới | C16: Quản lý Mức khấu trừ | D16: Bỏ qua | E16: Đang ở màn hình Tạo | F16: Không lưu dữ liệu | G16: 1. Nhấn Bỏ qua | H16: Quay về màn hình danh sách, không tạo bản ghi | I16: Đạt
... A22: TC-17 | B22: Là Admin tôi có thể nhấn vào icon xóa mức khẩu trừ | C22: Quản lý Mức khấu trừ | D22: Xóa | E22: Đang ở màn hình danh sách mức khấu trừ | F22: Hiển thị giao diện xóa | G22: 1. Nhấn vào icon xóa | H22: Hiển thị popup xóa | I22: Đạt
A23: TC-18 | B23: "Là Admin tôi có thể xóa khi nhấn vào nút "Có, Xóa ngay" | C23: Quản lý Mức khấu trừ | D23: Xóa | E23: Đang ở popup xóa | G23: 1. Nhấn vào nút "Có, Xóa ngay" | H23: Hiển thị thông báo xóa thành công | I23: Đạt
A24: TC-19 | B24: "Là Admin khi nhấn vào nút | C24: Quản lý Mức khấu trừ | D24: Xóa | E24: Đang ở popup xóa | G24: 1. Nhấn vào nút "Đóng" | H24: Đóng popup và không xóa quay lại màn hình khẩu trừ | I24: Đạt
A25: TC-20 | B25: Là Admin khi tôi xóa mức khẩu trừ đang được sử dụng sẽ hiển thị lỗi không cho phép xóa | C25: Quản lý Mức khấu trừ | D25: Xóa | E25: Mức khấu trừ đang được dùng trong phạm vi BH | F25: Kiểm tra trường bắt buộc | G25: 1. Nhấn vào nút "Có, Xóa ngay" | H25: Hiển thị thông báo không thể xóa | I25: Đạt

Sheet BeeOS - Quản lý Loại hình BH
B1: Tên chức năng | D1: Quản lý Loại hình Bảo Hiểm | G1: Tổng TCs | H1: Đạt | I1: Không đạt | J1: Chưa xong
B2: Người tạo | D2: Levi | G2: =COUNTIF(A6:A78,"TC-??") -> 26 | H2: =COUNTIF(I4:I935,"Đạt") -> 26 | I2: =COUNTIF(I4:I935,"Không Đạt") -> 0 | J2: =COUNTIF(I4:I935,"Chưa Xong") -> 0
B3: Ngày Tạo | D3: 45980 | G3: =SUM(H3+I3+J3) -> 1 | H3: =H2/G2 -> 1 | I3: =I2/G2 -> 0 | J3: =J2/G2 -> 0
A5: ID | B5: User Story | C5: Chức năng chính | D5: Chức năng con | E5: Điều kiện tiên quyết | F5: Mô tả | G5: Các bước thực hiện | H5: Kết quả mong đợi | I5: Kết quả thực tế
A6: TC-01 | B6: Là Admin, tôi muốn truy cập màn hình Quản lý Loại hình BH | C6: Quản lý Loại hình BH | D6: Truy cập màn hình | E6: Admin đã đăng nhập | F6: Kiểm tra truy cập màn hình danh sách | G6: 1. Đăng nhập bằng tài khoản Admin;2. Chọn Quản lý chung;3. Chọn Loại hình bảo hiểm | H6: Hệ thống hiển thị màn hình Loại hình bảo hiểm | I6: Đạt
A7: TC-02 | B7: Là Admin, tôi muốn xem danh sách Loại hình BH | C7: Quản lý Loại hình BH | D7: Xem danh sách | E7: Đang ở màn hình danh sách | F7: Hiển thị danh sách loại hình | G7: 1. Truy cập màn hình danh sách | H7: Hiển thị danh sách gồm: Tên viết tắt, Tên đầy đủ và Phạm vi bảo hiểm, nút Sửa/ Xóa | I7: Đạt
A8: TC-03 | B8: Là Admin, tôi muốn sắp xếp theo thứ tự tăng dần và giảm dần cho cột Tên viết tắt | C8: Quản lý Loại hình BH | D8: Xem danh sách | E8: Đang ở màn hình danh sách | F8: Sắp xếp tăng dần và giảm dần cho cột Tên viết tắt | G8: 1. Sắp xếp cột Tên viết tắt tăng dần 2. Sắp xếp cột tên viết tắt giảm dần | H8: 1. Hiển thị đúng tên viết tắt tăng dần 2. Hiển thị đúng tên viết tắt tăng dần | I8: Đạt
A9: TC-04 | B9: Là Admin, tôi muốn sắp xếp theo thứ tự tăng dần và giảm dần cho cột Tên đầy đủ | C9: Quản lý Loại hình BH | D9: Xem danh sách | E9: Đang ở màn hình danh sách | F9: Sắp xếp tăng dần và giảm dần cho cột Tên đầy đủ | G9: 1. Sắp xếp cột Tên đầy đủ tăng dần 2. Sắp xếp cột tên đầy đủ giảm dần | H9: 1. Hiển thị đúng tên đầy đủ tăng dần 2. Hiển thị đúng tên đầy đủ tăng dần | I9: Đạt
A10: TC-05 | B10: Là Admin, tôi muốn chọn số hàng hiển thị trong 1 trang | C10: Quản lý Loại hình BH | D10: Phân trang | E10: Có nhiều hơn 1 trang dữ liệu | F10: Chọn số item hiển thị trong trang | G10: 1. Nhấn chọn số hàng mỗi trang | H10: Hiển thị đúng số item trong 1 trang | I10: Đạt
A11: TC-06 | B11: Là Admin, tôi muốn phân trang danh sách | C11: Quản lý Loại hình BH | D11: Phân trang | E11: Có nhiều hơn 1 trang dữ liệu | F11: Điều hướng danh sách | G11: 1. Nhấn Trang tiếp / Trang trước;2. Chọn số trang | H11: Dữ liệu hiển thị đúng theo trang được chọn | I11: Đạt
A12: TC-07 | B12: Là Admin, tôi muốn mở màn hình tạo Loại hình BH | C12: Quản lý Loại hình BH | D12: Mở form tạo mới | E12: Đang ở màn hình danh sách | F12: Điều hướng sang màn hình tạo | G12: 1. Nhấn + Thêm loại hình bảo hiểm | H12: Mở màn hình Tạo loại hình bảo hiểm | I12: Đạt
A13: TC-08 | B13: Là Admin, tôi muốn tạo Loại hình BH hợp lệ | C13: Quản lý Loại hình BH | D13: Tạo mới | E13: Đang ở màn hình Tạo | F13: Tạo mới thành công | G13: 1. Nhập Tên loại hình bảo hiểm đầy đủ;2. Nhập tên viết tắt 3. Nhập Tài sản và quyền lợi bảo hiểm;4. Thêm Phạm vi bảo hiểm;5. Chọn Nhóm tổn thất;6. Chọn Bộ điều khoản bổ sung;7. Nhấn Tạo loại hình bảo hiểm | H13: Loại hình BH được tạo thành công và hiển thị trong danh sách | I13: Đạt
A14: TC-09 | B14: Là Admin, tôi không thể tạo khi thiếu Tên loại hình BH | C14: Quản lý Loại hình BH | D14: Validate dữ liệu | E14: Đang ở màn hình Tạo | F14: Kiểm tra trường bắt buộc | G14: 1. Để trống Tên loại hình BH đầy đủ ;2. Nhấn Tạo loại hình bảo hiểm | H14: Hiển thị thông báo Trường này là bắt buộc | I14: Đạt
A15: TC-10 | B15: Là Admin, tôi không thể tạo khi thiếu Tên loại hình BH | C15: Quản lý Loại hình BH | D15: Validate dữ liệu | E15: Đang ở màn hình Tạo | F15: Kiểm tra trường bắt buộc | G15: 1. Để trống Tên viết tắt BH;2. Nhấn Tạo loại hình bảo hiểm | H15: Hiển thị thông báo Trường này là bắt buộc | I15: Đạt
A16: TC-11 | B16: Là Admin, tôi không thể tạo khi thiếu Tài sản và quyền lợi BH | C16: Quản lý Loại hình BH | D16: Validate dữ liệu | E16: Đang ở màn hình Tạo | F16: Kiểm tra trường bắt buộc | G16: 1. Để trống Tài sản và quyền lợi BH;2. Nhấn Tạo loại hình bảo hiểm | H16: Hiển thị thông báo lỗi bắt buộc | I16: Đạt
... A31: TC-22 | B31: Là Admin, tôi muốn quay lại danh sách từ màn hình Tạo/Sửa | C31: Quản lý Loại hình BH | D31: Quay lại | E31: Đang ở màn hình Tạo/Sửa | F31: Điều hướng | G31: 1. Nhấn Quay lại | H31: Quay về màn hình danh sách | I31: Đạt

Sheet BeeOS - Quản lý Bộ ĐK bổ sung
B1: Tên chức năng | D1: Quản lý Bộ Điều khoản bổ sung | G1: Tổng TCs | H1: Đạt | I1: Không đạt | J1: Chưa xong
B2: Người tạo | D2: Levi | G2: =COUNTIF(A6:A74,"TC-??") -> 19 | H2: =COUNTIF(I4:I931,"Đạt") -> 19 | I2: =COUNTIF(G4:G931,"Không Đạt") -> 0 | J2: =COUNTIF(G4:G931,"Chưa Xong") -> 0
B3: Ngày Tạo | D3: 45981 | G3: =SUM(H3+I3+J3) -> 1 | H3: =H2/G2 -> 1 | I3: =I2/G2 -> 0 | J3: =J2/G2 -> 0
A5: ID | B5: User Story | C5: Chức năng chính | D5: Chức năng con | E5: Điều kiện tiên quyết | F5: Mô tả | G5: Các bước thực hiện | H5: Kết quả mong đợi | I5: Kết quả thực tế
A6: TC-01 | B6: Là Admin, tôi muốn xem danh sách Bộ điều khoản bổ sung | C6: Quản lý Bộ điều khoản bổ sung | D6: Xem danh sách | E6: Admin đã đăng nhập | F6: Kiểm tra hiển thị danh sách | G6: 1. Truy cập menu Quản lý chung → Điều khoản bổ sung; 2. Quan sát danh sách | H6: Danh sách hiển thị đầy đủ các Bộ điều khoản;Hiển thị đúng tên | I6: Đạt
A7: TC-02 | B7: Là Admin, tôi muốn tìm kiếm Bộ điều khoản bổ sung | C7: Quản lý Bộ điều khoản bổ sung | D7: Tìm kiếm | E7: Có dữ liệu trong hệ thống | F7: Kiểm tra chức năng tìm kiếm | G7: 1. Nhập từ khóa vào ô Tìm kiếm; 2. Quan sát kết quả | H7: Danh sách lọc đúng theo từ khóa | I7: Đạt
A8: TC-03 | B8: Là Admin, tôi muốn sắp xếp theo thứ tự tăng dần cho cột Tên bộ điều khoản bổ sung | C8: Quản lý Bộ điều khoản bổ sung | D8: Xem danh sách | E8: Đang ở màn hình danh sách | F8: Sắp xếp tăng dần cho cột tên bộ điều khoản bổ sung | G8: 1. Sắp xếp cột Tên bộ điều khoản bổ sung | H8: 1. Hiển thị đúng Tên bộ điều khoản bổ sung theo thứ tự tăng dần | I8: Đạt
A9: TC-04 | B9: Là Admin, tôi muốn sắp xếp theo thứ tự giảm dần cho cột Tên điều khoản bổ sung | C9: Quản lý Bộ điều khoản bổ sung | D9: Xem danh sách | E9: Đang ở màn hình danh sách | F9: Sắp xếp giảm dần cho cột tên bộ điều khoản bổ sung | G9: 1. Sắp xếp cột Tên bộ điều khoản bổ sung | H9: 1. Hiển thị đúng Tên bộ điều khoản bổ sung theo thứ tự giảm dần | I9: Đạt
A10: TC-05 | B10: Là Admin, tôi muốn mở màn hình tạo mới Bộ điều khoản bổ sung | C10: Quản lý Bộ điều khoản bổ sung | D10: Tạo mới | E10: Admin đã đăng nhập | F10: Kiểm tra điều hướng nút tạo | G10: 1. Nhấn nút “+ Thêm bộ điều khoản bổ sung” | H10: Mở màn hình “Tạo Bộ điều khoản bổ sung” | I10: Đạt
A11: TC-06 | B11: Là Admin, tôi muốn tạo mới Bộ điều khoản bổ sung hợp lệ | C11: Quản lý Bộ điều khoản bổ sung | D11: Lưu tạo mới | E11: Nhập đầy đủ thông tin bắt buộc | F11: Kiểm tra tạo mới thành công | G11: 1. Nhập Tên bộ điều khoản 2. Nhập Category 4. Thêm 1 điều khoản 5. Nhấn “Tạo Bộ điều khoản bổ sung” | H11: Tạo thành công;Hiển thị bộ điều khoản mới trong danh sách | I11: Đạt
A12: TC-07 | B12: Là Admin, tôi không muốn tạo khi thiếu thông tin bắt buộc | C12: Quản lý Bộ điều khoản bổ sung | D12: Validate dữ liệu | E12: Chưa nhập đủ trường bắt buộc | F12: Kiểm tra validate form | G12: 1. Bỏ trống Tên 2. Nhấn Tạo | H12: Hiển thị thông báo lỗi;Không cho lưu | I12: Đạt
A13: TC-08 | B13: Là Admin, tôi muốn chọn nhiều điều khoản trong modal | C13: Quản lý Bộ điều khoản bổ sung | D13: Chọn điều khoản | E13: Modal đang mở | F13: Kiểm tra chọn nhiều item | G13: 1. Tick chọn nhiều điều khoản 2. Nhấn “Thêm điều khoản” | H13: Các điều khoản được thêm vào danh sách | I13: Đạt
A14: TC-09 | B14: Là Admin, tôi muốn tìm điều khoản trong modal | C14: Quản lý Bộ điều khoản bổ sung | D14: Tìm trong modal | E14: Có nhiều điều khoản | F14: Kiểm tra tìm kiếm trong modal | G14: 1. Nhập từ khóa trong modal | H14: Danh sách điều khoản lọc đúng | I14: Đạt
A15: TC-10 | B15: Là Admin, tôi muốn sắp xếp lại thứ tự điều khoản | C15: Quản lý Bộ điều khoản bổ sung | D15: Sắp xếp | E15: Danh sách có nhiều điều khoản | F15: Kiểm tra drag & drop | G15: 1. Kéo thả điều khoản để đổi vị trí | H15: Thứ tự được cập nhật đúng | I15: Đạt
A16: TC-11 | B16: Là Admin, tôi muốn xóa điều khoản khỏi bộ | C16: Quản lý Bộ điều khoản bổ sung | D16: Xóa điều khoản | E16: Đã có điều khoản | F16: Kiểm tra xóa item | G16: 1. Nhấn icon xóa tại điều khoản | H16: Điều khoản bị xóa khỏi danh sách | I16: Đạt
... A24: TC-19 | B24: Là Admin, tôi không thể xóa bộ điều khoản bổ sung đã được sử dụng | C24: Quản lý Bộ điều khoản bổ sung | D24: Xóa | E24: Bộ điều khoản bổ sung đã được dùng trong loại hình bảo hiểm | F24: Kiểm tra ràng buộc | G24: 1. Nhấn Xóa | H24: Hiển thị thông báo không thể xóa | I24: Đạt

Sheet BeeOS - Quản lý ĐK bổ sung
B1: Tên chức năng | D1: Quản lý Điều khoản bổ sung | G1: Tổng TCs | H1: Đạt | I1: Không đạt | J1: Chưa xong
B2: Người tạo | D2: Levi | G2: =COUNTIF(A6:A76,"TC-??") -> 15 | H2: =COUNTIF(I4:I932,"Đạt") -> 15 | I2: =COUNTIF(I4:I932,"Không Đạt") -> 0 | J2: =COUNTIF(I4:I932,"Chưa Xong") -> 0
B3: Ngày Tạo | D3: 46013 | G3: =SUM(H3+I3+J3) -> 1 | H3: =H2/G2 -> 1 | I3: =I2/G2 -> 0 | J3: =J2/G2 -> 0
A5: ID | B5: User Story | C5: Chức năng chính | D5: Chức năng con | E5: Điều kiện tiên quyết | F5: Mô tả | G5: Các bước thực hiện | H5: Kết quả mong đợi | I5: Kết quả thực tế
A6: TC-01 | B6: Là Admin, tôi muốn truy cập màn hình quản lý Điều khoản bổ sung | C6: Quản lý Điều khoản bổ sung | D6: Truy cập màn hình | E6: User đăng nhập với quyền Admin | F6: Kiểm tra truy cập menu Điều khoản bổ sung | G6: 1. Đăng nhập hệ thống;2. Chọn menu Quản lý chung → Điều khoản bổ sung | H6: Hệ thống hiển thị màn hình danh sách Điều khoản bổ sung | I6: Đạt
A7: TC-02 | B7: Là Admin, tôi muốn xem danh sách Điều khoản bổ sung | C7: Quản lý Điều khoản bổ sung | D7: Xem danh sách | E7: Có dữ liệu điều khoản bổ sung | F7: Kiểm tra hiển thị danh sách | G7: 1. Truy cập màn hình Điều khoản bổ sung | H7: Hiển thị danh sách gồm:Tên điều khoản;Thông tin chi tiết;Trạng thái; xóa | I7: Đạt
A8: TC-03 | B8: Là Admin, tôi muốn tìm kiếm Điều khoản bổ sung | C8: Quản lý Điều khoản bổ sung | D8: Tìm kiếm | E8: Có nhiều điều khoản trong hệ thống | F8: Kiểm tra chức năng tìm kiếm | G8: 1. Nhập từ khóa vào ô Tìm kiếm;2. Quan sát danh sách | H8: Danh sách lọc đúng theo từ khóa;Không reload trang | I8: Đạt
A9: TC-04 | B9: Là Admin, tôi muốn sắp xếp theo thứ tự tăng dần cho cột Tên điều khoản bổ sung | C9: Quản lý Loại hình BH | D9: Xem danh sách | E9: Đang ở màn hình danh sách | F9: Sắp xếp tăng dần cho cột tên điều khoản bổ sung | G9: 1. Sắp xếp cột Tên điều khoản bổ sung | H9: 1. Hiển thị đúng Tên điều khoản bổ sung | I9: Đạt
A10: TC-05 | B10: Là Admin, tôi muốn sắp xếp theo thứ tự giảm dần cho cột Tên điều khoản bổ sung | C10: Quản lý Loại hình BH | D10: Xem danh sách | E10: Đang ở màn hình danh sách | F10: Sắp xếp giảm dần cho cột tên điều khoản bổ sung | G10: 1. Sắp xếp cột Tên điều khoản bổ sung | H10: 1. Hiển thị đúng Tên điều khoản bổ sung | I10: Đạt
A11: TC-06 | B11: Là Admin, tôi muốn mở màn hình tạo Điều khoản bổ sung | C11: Quản lý Điều khoản bổ sung | D11: Tạo mới | E11: User có quyền Admin | F11: Kiểm tra điều hướng tạo mới | G11: 1. Nhấn nút “+ Thêm điều khoản bổ sung” | H11: Mở màn hình “Tạo điều khoản bổ sung” | I11: Đạt
A12: TC-07 | B12: Là Admin, tôi muốn tạo Điều khoản bổ sung mới | C12: Quản lý Điều khoản bổ sung | D12: Lưu tạo mới | E12: Nhập đầy đủ dữ liệu hợp lệ | F12: Kiểm tra tạo mới thành công | G12: 1. Nhập Tên điều khoản;2. Nhập Thông tin chi tiết;3. Nhấn “Tạo điều khoản bổ sung” | H12: Điều khoản được tạo thành công;Hiển thị trong danh sách;Thông báo thành công | I12: Đạt
A13: TC-08 | B13: Là Admin, tôi muốn kiểm tra validate khi tạo mới | C13: Quản lý Điều khoản bổ sung | D13: Validate dữ liệu | E13: Đang ở màn hình tạo mới | F13: Kiểm tra dữ liệu bắt buộc | G13: 1. Để trống Tên điều khoản;2. Nhấn Lưu | H13: Hiển thị cảnh báo bắt buộc nhập Tên điều khoản;Không tạo dữ liệu | I13: Đạt
A14: TC-09 | B14: Là Admin, tôi muốn hủy tạo mới | C14: Quản lý Điều khoản bổ sung | D14: Bỏ qua | E14: Đang ở màn hình tạo mới | F14: Kiểm tra nút Bỏ qua | G14: 1. Nhấn nút “Bỏ qua” | H14: Quay về màn hình danh sách;Không lưu dữ liệu | I14: Đạt
A15: TC-10 | B15: Là Admin, tôi muốn mở màn hình chỉnh sửa Điều khoản bổ sung | C15: Quản lý Điều khoản bổ sung | D15: Chỉnh sửa | E15: Điều khoản đã tồn tại | F15: Kiểm tra điều hướng chỉnh sửa | G15: 1. Nhấn icon chỉnh sửa tại dòng điều khoản | H15: Mở màn hình “Sửa điều khoản bổ sung” | I15: Đạt
A16: TC-11 | B16: Là Admin, tôi muốn chỉnh sửa thông tin Điều khoản bổ sung | C16: Quản lý Điều khoản bổ sung | D16: Lưu chỉnh sửa | E16: Dữ liệu chỉnh sửa hợp lệ | F16: Kiểm tra lưu chỉnh sửa | G16: 1. Thay đổi tên / thông tin / trạng thái;2. Nhấn “Lưu chỉnh sửa” | H16: Dữ liệu được cập nhật;Danh sách hiển thị thông tin mới | I16: Đạt
... A20: TC-15 | B20: Là Admin, tôi không thể điều khoản bổ sung đã được sử dụng | C20: Quản lý Phạm vi Bảo hiểm | D20: Xóa | E20: điều khoản bổ sung đã được dùng trong bộ điều khoản bổ sung | F20: Kiểm tra ràng buộc | G20: 1. Nhấn Xóa | H20: Hiển thị thông báo không thể xóa | I20: Đạt

Sheet BeeOS - Quản lý Nhóm Tổn Thất
B1: Tên chức năng | D1: Quản lý Nhóm Tổn thất | G1: Tổng TCs | H1: Đạt | I1: Không đạt | J1: Chưa xong
B2: Người tạo | D2: Levi | G2: =COUNTIF(A6:A74,"TC-??") -> 16 | H2: =COUNTIF(I4:I931,"Đạt") -> 16 | I2: =COUNTIF(G4:G931,"Không Đạt") -> 0 | J2: =COUNTIF(G4:G931,"Chưa Xong") -> 0
B3: Ngày Tạo | D3: 45981 | G3: =SUM(H3+I3+J3) -> 1 | H3: =H2/G2 -> 1 | I3: =I2/G2 -> 0 | J3: =J2/G2 -> 0
A5: ID | B5: User Story | C5: Chức năng chính | D5: Chức năng con | E5: Điều kiện tiên quyết | F5: Mô tả | G5: Các bước thực hiện | H5: Kết quả mong đợi | I5: Kết quả thực tế
A6: TC-01 | B6: Là Admin, tôi muốn truy cập màn hình Quản lý Nhóm tổn thất | C6: Quản lý Nhóm tổn thất | D6: Truy cập màn hình | E6: Admin đã đăng nhập hệ thống | F6: Kiểm tra khả năng truy cập màn hình danh sách | G6: 1. Đăng nhập bằng tài khoản Admin;2. Chọn Quản lý chung;3. Chọn Nhóm tổn thất | H6: Hệ thống hiển thị màn hình Quản lý Nhóm tổn thất | I6: Đạt
A7: TC-02 | B7: Là Admin, tôi muốn xem danh sách Nhóm tổn thất | C7: Quản lý Nhóm tổn thất | D7: Xem danh sách | E7: Đang ở màn hình danh sách | F7: Hiển thị danh sách nhóm tổn thất | G7: 1. Truy cập màn hình danh sách | H7: Hiển thị các cột: Tên nhóm tổn thất, nút Sửa, nút Xóa | I7: Đạt
A8: TC-03 | B8: Là Admin, tôi muốn tìm kiếm Nhóm tổn thất | C8: Quản lý Nhóm tổn thất | D8: Tìm kiếm | E8: Có dữ liệu nhóm tổn thất | F8: Tìm theo tên nhóm tổn thất | G8: 1. Nhập từ khóa vào ô Tìm kiếm | H8: Danh sách hiển thị đúng các nhóm phù hợp | I8: Đạt
A9: TC-04 | B9: Là Admin, tôi muốn phân trang danh sách | C9: Quản lý Nhóm tổn thất | D9: Phân trang | E9: Có nhiều hơn 1 trang dữ liệu | F9: Điều hướng danh sách | G9: 1. Nhấn Trang tiếp;2. Nhấn Trang trước;3. Chọn số trang | H9: Danh sách hiển thị đúng theo trang được chọn | I9: Đạt
A10: TC-05 | B10: Là Admin, tôi muốn mở màn hình tạo Nhóm tổn thất | C10: Quản lý Nhóm tổn thất | D10: Mở form tạo mới | E10: Đang ở màn hình danh sách | F10: Điều hướng tạo mới | G10: 1. Nhấn + Thêm Nhóm tổn thất | H10: Hệ thống mở màn hình Tạo nhóm tổn thất | I10: Đạt
A11: TC-06 | B11: Là Admin, tôi muốn tạo Nhóm tổn thất với dữ liệu hợp lệ | C11: Quản lý Nhóm tổn thất | D11: Tạo mới | E11: Đang ở màn hình Tạo | F11: Tạo nhóm tổn thất thành công | G11: 1. Nhập Tên nhóm tổn thất;2. Chọn Trạng thái;3. Nhấn Tạo nhóm tổn thất | H11: Nhóm tổn thất được tạo và hiển thị trong danh sách | I11: Đạt
A12: TC-07 | B12: Là Admin, tôi không thể tạo khi thiếu Tên nhóm tổn thất | C12: Quản lý Nhóm tổn thất | D12: Validate dữ liệu | E12: Đang ở màn hình Tạo | F12: Kiểm tra trường bắt buộc | G12: 1. Để trống Tên nhóm tổn thất;2. Nhấn Tạo nhóm tổn thất | H12: Hiển thị thông báo lỗi yêu cầu nhập Tên nhóm tổn thất | I12: Đạt
A13: TC-08 | B13: Là Admin tôi không thể tạo khi nhập tên nhóm tổn thất đã tồn tại | C13: Quản lý Nhóm tổn thất | D13: Validate dữ liệu | E13: Đang ở màn hình Tạo | F13: Kiểm tra trường bắt buộc | G13: 1. Nhập tên nhóm tổn thất đã tồn tại 2. Nhấn "Tạo nhóm tổn thất" | H13: Hiển thị thông báo Tên nhóm tổn thất đã tồn tại | I13: Đạt
A14: TC-09 | B14: Là Admin, tôi muốn hủy tạo mới | C14: Quản lý Nhóm tổn thất | D14: Bỏ qua | E14: Đang ở màn hình Tạo | F14: Không lưu dữ liệu | G14: 1. Nhấn Bỏ qua | H14: Quay về màn hình danh sách, không tạo nhóm mới | I14: Đạt
A15: TC-10 | B15: Là Admin, tôi muốn mở màn hình sửa Nhóm tổn thất | C15: Quản lý Nhóm tổn thất | D15: Mở form chỉnh sửa | E15: Có sẵn nhóm tổn thất | F15: Điều hướng chỉnh sửa | G15: 1. Nhấn icon Sửa tại 1 bản ghi | H15: Mở màn hình Sửa nhóm tổn thất | I15: Đạt
A16: TC-11 | B16: Là Admin, tôi muốn cập nhật Nhóm tổn thất | C16: Quản lý Nhóm tổn thất | D16: Chỉnh sửa | E16: Đang ở màn hình Sửa | F16: Lưu thay đổi | G16: 1. Thay đổi Tên;2. Nhấn Lưu chỉnh sửa | H16: Thông tin nhóm tổn thất được cập nhật thành công | I16: Đạt
... A21: TC-16 | B21: Là Admin, tôi muốn quay lại danh sách từ màn hình Tạo/Sửa | C21: Quản lý Nhóm tổn thất | D21: Quay lại | E21: Đang ở màn hình Tạo hoặc Sửa | F21: Điều hướng quay lại | G21: 1. Nhấn Quay lại | H21: Quay về màn hình danh sách Nhóm tổn thất | I21: Đạt

Sheet BeeOS - Quản lý Công ty BH
B1: Tên chức năng | D1: Quản lý Công ty Bảo Hiểm | G1: Tổng TCs | H1: Đạt | I1: Không đạt | J1: Chưa xong
B2: Người tạo | D2: Levi | G2: =COUNTIF(A6:A89,"TC-??") -> 34 | H2: =COUNTIF(I4:I946,"Đạt") -> 34 | I2: =COUNTIF(G4:G946,"Không Đạt") -> 0 | J2: =COUNTIF(G4:G946,"Chưa Xong") -> 0
B3: Ngày Tạo | D3: 45982 | G3: =SUM(H3+I3+J3) -> 1 | H3: =H2/G2 -> 1 | I3: =I2/G2 -> 0 | J3: =J2/G2 -> 0
A5: ID | B5: User Story | C5: Chức năng chính | D5: Chức năng con | E5: Điều kiện tiên quyết | F5: Mô tả | G5: Các bước thực hiện | H5: Kết quả mong đợi | I5: Kết quả thực tế
A6: TC-01 | B6: Là Admin/Underwriter/Claim Oficer, tôi muốn truy cập màn hình Quản lý Công ty Bảo hiểm | C6: Quản lý Công ty Bảo hiểm | D6: Truy cập màn hình | E6: Admin đã đăng nhập hệ thống | F6: Kiểm tra khả năng truy cập màn hình danh sách | G6: 1. Đăng nhập bằng tài khoản Admin;2. Chọn Quản lý chung;3. Chọn Công ty bảo hiểm | H6: Hệ thống hiển thị màn hình Quản lý Công ty Bảo hiểm | I6: Đạt
A7: TC-02 | B7: Là Admin/Underwriter/Claim Oficer, tôi muốn xem danh sách Công ty Bảo hiểm | C7: Quản lý Công ty Bảo hiểm | D7: Xem danh sách | E7: Đang ở màn hình danh sách | F7: Hiển thị danh sách công ty | G7: 1. Truy cập màn hình danh sách | H7: Hiển thị các cột: Tên đầy đủ, tên viết tắt, nút Sửa, nút Xóa | I7: Đạt
A8: TC-03 | B8: Là Admin/Underwriter/Claim Oficer, tôi muốn tìm kiếm Công ty Bảo hiểm | C8: Quản lý Công ty Bảo hiểm | D8: Tìm kiếm | E8: Có dữ liệu công ty | F8: Tìm theo tên công ty | G8: 1. Nhập từ khóa vào ô Tìm kiếm công ty bảo hiểm | H8: Danh sách hiển thị đúng các công ty phù hợp | I8: Đạt
A9: TC-04 | B9: Là Admin/Underwriter/Claim Oficer, tôi muốn phân trang danh sách | C9: Quản lý Công ty Bảo hiểm | D9: Phân trang | E9: Có nhiều hơn 1 trang dữ liệu | F9: Điều hướng danh sách | G9: 1. Nhấn Trang tiếp;2. Nhấn Trang trước;3. Chọn số trang | H9: Danh sách hiển thị đúng theo trang được chọn | I9: Đạt
A10: TC-05 | B10: Là Admin/Underwriter/Claim Oficer, tôi muốn sắp xếp theo thứ tự tăng dần cho cột Tên đầy đủ | C10: Quản lý Công ty Bảo hiểm | D10: Xem danh sách | E10: Đang ở màn hình danh sách | F10: Sắp xếp tăng dần cho cột Tên đầy đủ | G10: 1. Sắp xếp cột Tên đầy đủ | H10: 1. Hiển thị đúng Tên đầy đủ theo danh sách tăng dần | I10: Đạt
A11: TC-06 | B11: Là Admin/Underwriter/Claim Oficer, tôi muốn sắp xếp theo thứ tự giảm dần cho cột Tên đầy đủ | C11: Quản lý Công ty Bảo hiểm | D11: Xem danh sách | E11: Đang ở màn hình danh sách | F11: Sắp xếp giảm dần cho cột Tên đầy đủ | G11: 1. Sắp xếp cột Tên đầy đủ | H11: 1. Hiển thị đúng Tên đầy đủ theo danh sách giảm dần | I11: Đạt
A12: TC-07 | B12: Là Admin/Underwriter/Claim Oficer, tôi muốn mở màn hình tạo Công ty Bảo hiểm | C12: Quản lý Công ty Bảo hiểm | D12: Mở form tạo mới | E12: Đang ở màn hình danh sách | F12: Điều hướng tạo mới | G12: 1. Nhấn + Thêm công ty bảo hiểm | H12: Hệ thống mở màn hình Tạo Công ty Bảo hiểm và UI hiển thị đúng với figma | I12: Đạt
A13: TC-08 | B13: Là Admin/Underwriter/Claim Oficer, tôi muốn tạo Công ty Bảo hiểm với dữ liệu hợp lệ | C13: Quản lý Công ty Bảo hiểm | D13: Tạo mới | E13: Đang ở màn hình Tạo | F13: Tạo công ty bảo hiểm thành công | G13: 1. Nhập Tên công ty bảo hiểm;2. Nhập tên viết tắt; 3. Nhập email 4. Nhập thông tin người phụ trách ;5. Nhấn Tạo công ty bảo hiểm | H13: Công ty bảo hiểm được tạo và hiển thị trong danh sách | I13: Đạt
A14: TC-09 | B14: Là Admin/Underwriter/Claim Oficer, tôi không thể tạo khi thiếu Tên công ty bảo hiểm | C14: Quản lý Công ty Bảo hiểm | D14: Validate dữ liệu | E14: Đang ở màn hình Tạo | F14: Kiểm tra trường bắt buộc | G14: 1. Để trống Tên công ty bảo hiểm;2. Nhấn Tạo công ty bảo hiểm | H14: Hiển thị thông báo lỗi yêu cầu nhập Tên công ty | I14: Đạt
A15: TC-10 | B15: Là Admin/Underwriter/Claim Oficer, tôi không thể tạo khi thiếu Chi nhánh | C15: Quản lý Công ty Bảo hiểm | D15: Validate dữ liệu | E15: Đang ở màn hình Tạo | F15: Kiểm tra trường bắt buộc | G15: 1. Để trống tên viết tắt;2. Nhấn Tạo công ty bảo hiểm | H15: Hiển thị thông báo lỗi yêu cầu nhập tên viết tắt | I15: Đạt
A16: TC-11 | B16: Là Admin/Underwriter/Claim Oficer, tôi không thể tạo khi chưa chọn Trạng thái | C16: Quản lý Công ty Bảo hiểm | D16: Validate dữ liệu | E16: Đang ở màn hình Tạo | F16: Kiểm tra trường bắt buộc | G16: 1. Không chọn Trạng thái;2. Nhấn Tạo công ty bảo hiểm | H16: Hiển thị thông báo yêu cầu chọn Trạng thái | I16: Đạt
... A39: TC-34 | B39: Là Admin/Underwriter/Claim Oficer, tôi muốn quay lại danh sách từ màn hình Tạo/Sửa | C39: Quản lý Công ty Bảo hiểm | D39: Quay lại | E39: Đang ở màn hình Tạo hoặc Sửa | F39: Điều hướng quay lại | G39: 1. Nhấn Quay lại | H39: Quay về màn hình danh sách Công ty Bảo hiểm | I39: Đạt

Sheet BeeOS - Quản lý P&L
B1: Tên chức năng | D1: Quản lý P&L | G1: Tổng TCs | H1: Đạt | I1: Không đạt | J1: Chưa xong
B2: Người tạo | D2: Levi | G2: =COUNTIF(A6:A102,"TC-??") -> 30 | H2: =COUNTIF(I4:I933,"Đạt") -> 30 | I2: =COUNTIF(I4:I933,"Không Đạt") -> 0 | J2: =COUNTIF(G4:G933,"Chưa Xong") -> 0
B3: Ngày Tạo | D3: 45982 | G3: =SUM(H3+I3+J3) -> 1 | H3: =H2/G2 -> 1 | I3: =I2/G2 -> 0 | J3: =J2/G2 -> 0
A5: ID | B5: User Story | C5: Chức năng chính | D5: Chức năng con | E5: Điều kiện tiên quyết | F5: Mô tả | G5: Các bước thực hiện | H5: Kết quả mong đợi | I5: Kết quả thực tế
A6: TC-01 | B6: Là Admin/Underwriter/Claim Oficer, tôi muốn truy cập màn hình Quản lý P&L | C6: Quản lý P&L | D6: Truy cập màn hình | E6: Admin đã đăng nhập | F6: Kiểm tra truy cập màn hình danh sách | G6: 1. Đăng nhập Admin;2. Chọn Quản lý chung;3. Chọn P&L | H6: Hiển thị màn hình Quản lý P&L | I6: Đạt
A7: TC-02 | B7: Là Admin/Underwriter/Claim Oficer, tôi muốn xem danh sách P&L | C7: Quản lý P&L | D7: Xem danh sách | E7: Đang ở màn hình danh sách | F7: Hiển thị dữ liệu P&L | G7: 1. Truy cạp màn hình danh sách | H7: Hiển thị các cột: P&L, Quản lý địa điểm, Trạng thái, Sửa, Xóa | I7: Đạt | J7: https://jira-vnv.vinova.sg/browse/BEEOS-580
A8: TC-03 | B8: Là Admin/Underwriter/Claim Oficer, tôi muốn tìm kiếm P&L | C8: Quản lý P&L | D8: Tìm kiếm | E8: Có dữ liệu P&L | F8: Tìm theo tên P&L | G8: 1. Nhập từ khóa vào ô Tìm kiếm | H8: Danh sách lọc đúng theo tên | I8: Đạt
A9: TC-04 | B9: Là Admin/Underwriter/Claim Oficer, tôi muốn phân trang danh sách | C9: Quản lý P&L | D9: Phân trang | E9: Có nhiều hơn 1 trang | F9: Điều hướng danh sách | G9: 1. Nhấn Trang tiếp / Trang trước | H9: Hiển thị đúng dữ liệu theo trang | I9: Đạt
A10: TC-05 | B10: Là Admin, tôi muốn sắp xếp theo thứ tự tăng dần cho cột P&L | C10: Quản lý P&L | D10: Xem danh sách | E10: Đang ở màn hình danh sách | F10: Sắp xếp tăng dần cho cột P&L | G10: 1. Sắp xếp cột Tên P&L | H10: 1. Hiển thị đúng P&L tăng dần | I10: Đạt
A11: TC-06 | B11: Là Admin, tôi muốn sắp xếp theo thứ tự giảm dần cho cột P&L | C11: Quản lý P&L | D11: Xem danh sách | E11: Đang ở màn hình danh sách | F11: Sắp xếp giảm dần cho cột P&L | G11: 1. Sắp xếp cột P&L | H11: 1. Hiển thị đúng P&L giảm dần | I11: Đạt
A12: TC-07 | B12: Là Admin/Underwriter/Claim Oficer, tôi muốn mở màn hình tạo P&L | C12: Quản lý P&L | D12: Mở form tạo | E12: Đang ở danh sách | F12: Điều hướng tạo mới | G12: 1. Nhấn + Thêm P&L | H12: Mở màn hình Tạo P&L mới và hiển thị UI giống với figma | I12: Đạt | J12: https://jira-vnv.vinova.sg/browse/BEEOS-582
A13: TC-08 | B13: Là Admin/Underwriter/Claim Oficer, tôi muốn tạo P&L hợp lệ | C13: Quản lý P&L | D13: Tạo mới | E13: Đang ở màn hình Tạo | F13: Tạo P&L thành công | G13: 1. Nhập Tên P&L;2. Nhập Ngành nghề kinh doanh; 3. Nhấn Tạo P&L mới | H13: P&L được tạo và hiển thị trong danh sách | I13: Đạt
A14: TC-09 | B14: Là Admin/Underwriter/Claim Oficer, tôi không thể tạo khi thiếu Tên P&L | C14: Quản lý P&L | D14: Validate dữ liệu | E14: Đang ở màn hình Tạo | F14: Kiểm tra bắt buộc | G14: 1. Để trống Tên P&L;2. Nhấn Tạo | H14: Hiển thị thông báo lỗi bắt buộc | I14: Đạt
A15: TC-10 | B15: Là Admin/Underwriter/Claim Oficer, tôi không thể tạo khi nhập trùng tên P&L | C15: Quản lý P&L | D15: Validate dữ liệu | E15: Đang ở màn hình Tạo | F15: Kiểm tra bắt buộc | G15: 1. Nhập tên P&L đã tồn tại trước đó;2. Nhấn Tạo | H15: Hiển thị thông báo tên P&L đã tồn tại | I15: Đạt
A16: TC-11 | B16: Là Admin/Underwriter/Claim Oficer, tôi muốn hủy tạo P&L | C16: Quản lý P&L | D16: Bỏ qua | E16: Đang ở màn hình Tạo | F16: Không lưu dữ liệu | G16: 1. Nhấn Bỏ qua | H16: Quay về danh sách, không tạo P&L | I16: Đạt
A17: TC-12 | B17: Là Admin/Underwriter/Claim Oficer, tôi muốn sửa thông tin P&L | C17: Quản lý P&L | D17: Chỉnh sửa | E17: Có sẵn P&L | F17: Mở form sửa | G17: 1. Nhấn icon Sửa | H17: Mở màn hình Sửa P&L và hiển thị UI giống với figma | I17: Đạt
A18: TC-13 | B18: Là Admin/Underwriter/Claim Oficer, tôi muốn lưu chỉnh sửa P&L | C18: Quản lý P&L | D18: Lưu chỉnh sửa | E18: Đang ở màn hình Sửa | F18: Cập nhật dữ liệu | G18: 1. Thay đổi thông tin;2. Nhấn Lưu chỉnh sửa | H18: Thông tin P&L được cập nhật | I18: Đạt
A19: TC-14 | B19: Là Admin/Underwriter/Claim Oficer, tôi không thể chỉnh sửa khi thiếu Tên P&L | C19: Quản lý P&L | D19: Validate dữ liệu | E19: Đang ở màn hình Sửa | F19: Kiểm tra bắt buộc | G19: 1. Để trống Tên P&L;2. Nhấn Lưu chỉnh sửa | H19: Hiển thị thông báo lỗi bắt buộc | I19: Đạt
A20: TC-15 | B20: Là Admin/Underwriter/Claim Oficer, tôi không thể chỉnh sửa khi nhập trùng tên P&L | C20: Quản lý P&L | D20: Validate dữ liệu | E20: Đang ở màn hình Sửa | F20: Kiểm tra bắt buộc | G20: 1. Nhập tên P&L đã tồn tại trước đó;2. Nhấn Lưu chỉnh sửa | H20: Hiển thị thông báo tên P&L đã tồn tại | I20: Đạt
A21: TC-16 | B21: Là Admin/Ubderwrite/ Claim tôi muốn mở màn hình xóa P&L | C21: Quản lý Công ty Bảo hiểm | D21: Xóa | E21: Đang ở mang hình danh sách | F21: Hiển thị màn hình xóa | G21: 1. Nhấn icon Xóa | H21: Hiển thị màn hình xóa và hiển thị UI giống với figma | I21: Đạt
A22: TC-17 | B22: Là Admin/Underwriter/Claim Oficer, tôi có thể xoa P&L khi địa diểm chưa được dùng | C22: Quản lý Công ty Bảo hiểm | D22: Ràng buộc dữ liệu | E22: Đang ở màn hình xóa | F22: Xóa thành công | G22: 1. Nhấn icon Xóa 2. Nhấn nút Xóa | H22: Hiển thị thông báo Xóa P&L thành công | I22: Đạt
A23: TC-18 | B23: Là Admin/Underwriter/Claim Oficer sẽ chuyển trạng thái khi vào xóa P&L nhưng có địa điểm đã được dùng | C23: Quản lý Công ty Bảo hiểm | D23: Ràng buộc dữ liệu | E23: Đang ở màn hình xóa | F23: Chuyển đổi trạng thái | G23: 1. Nhấn icon Xóa 2. Nhấn nút Xóa | H23: Chuyển đổi trạng thái từ đang hoạt động sang không hoạt động | I23: Đạt
A24: TC-19 | B24: Là Admin/Underwriter/Claim Oficer, tôi muốn truy cập Quản lý địa điểm của P&L | C24: Quản lý P&L | D24: Quản lý địa điểm | E24: Có sẵn P&L | F24: Điều hướng danh sách địa điểm | G24: 1. Nhấn Quản lý địa điểm/ đối tượng BH | H24: Mở màn hình danh sách địa điểm của P&L | I24: Đạt
... A28: TC-23 | B28: Là Admin/Underwriter/Claim Oficer, tôi không thể tạo Địa điểm khi thiếu Tên | C28: Quản lý Địa điểm | D28: Validate | E28: Đang ở màn hình Tạo | F28: Kiểm tra bắt buộc | G28: 1. Để trống Địa điểm/ đối tượng BH;2. Nhấn Tạo | H28: Hiển thị thông báo lỗi | I28: Đạt
A29: TC-24 | B29: Là Admin/Underwriter/Claim Oficer, tôi không thể tạo Địa điểm khi nhập tên địa điểm đã tồn tại | C29: Quản lý Địa điểm | D29: Validate | E29: Đang ở màn hình Tạo | G29: 1. Tạo địa điểm đã tồn tại 2. Nhấn Tạo | H29: Hiển thị thông báo lỗi | I29: Đạt
A30: TC-25 | B30: Là Admin/Underwriter/Claim Oficer, tôi muốn sửa Địa điểm | C30: Quản lý Địa điểm | D30: Chỉnh sửa | E30: Có sẵn địa điểm | F30: Mở form sửa | G30: 1. Nhấn icon Sửa | H30: Mở màn hình Sửa địa điểm | I30: Đạt
A31: TC-26 | B31: Là Admin/Underwriter/Claim Oficer, tôi muốn lưu chỉnh sửa Địa điểm | C31: Quản lý Địa điểm | D31: Lưu chỉnh sửa | E31: Đang ở màn hình Sửa | F31: Cập nhật dữ liệu | G31: 1. Thay đổi thông tin;2. Nhấn Lưu chỉnh sửa | H31: Địa điểm được cập nhật | I31: Đạt
A32: TC-27 | B32: Là Admin/Underwriter/Claim Oficer, tôi không thể chỉnh sửa Địa điểm khi nhập tên địa điểm đã tồn tại | C32: Quản lý Địa điểm | D32: Validate | E32: Đang ở màn hình Sửa | G32: 1. Tạo địa điểm đã tồn tại 2. Nhấn sửa | H32: Hiển thị thông báo lỗi | I32: Đạt
A33: TC-28 | B33: Là Admin/Underwriter/Claim Oficer, tôi muốn xóa Địa điểm | C33: Quản lý Địa điểm | D33: Xóa | E33: Địa điểm chưa được sử dụng | F33: Xóa bản ghi | G33: 1. Nhấn icon Xóa;2. Xác nhận | H33: Địa điểm bị xóa | I33: Đạt
A34: TC-29 | B34: Là Admin/Underwriter/Claim Oficer, khi xóa địa điểm đã được sử dụng sẽ chuyển từ đang hoạt động sang không hoạt động | C34: Quản lý Địa điểm | D34: Ràng buộc | E34: Địa điểm đã gán hồ sơ | F34: Kiểm tra ràng buộc | G34: 1. Nhấn Xóa | H34: Chuyển đổi trạng thái từ đang hoạt động sang không hoạt động | I34: Đạt
A35: TC-30 | B35: Là Admin/Underwriter/Claim Oficer, tôi muốn quay lại danh sách P&L | C35: Quản lý P&L | D35: Quay lại | E35: Đang ở màn hình Địa điểm/Tạo/Sửa | F35: Điều hướng | G35: 1. Nhấn Quay lại | H35: Quay về màn hình danh sách P&L | I35: Đạt

Sheet BeeOS - Quản lý địa điểm
B1: Tên chức năng | D1: Quản lý Địa điểm/ Đối tượng BH | G1: Tổng TCs | H1: Đạt | I1: Không đạt | J1: Chưa xong
B2: Người tạo | D2: Lani | G2: =COUNTIF(A6:A77,"TC-??") -> 23 | H2: =COUNTIF(I4:I934,"Đạt") -> 23 | I2: =COUNTIF(G4:G934,"Không Đạt") -> 0 | J2: =COUNTIF(G4:G934,"Chưa Xong") -> 0
B3: Ngày Tạo | D3: 46057 | G3: =SUM(H3+I3+J3) -> 1 | H3: =H2/G2 -> 1 | I3: =I2/G2 -> 0 | J3: =J2/G2 -> 0
A5: ID | B5: User Story | C5: Chức năng chính | D5: Chức năng con | E5: Điều kiện tiên quyết | F5: Mô tả | G5: Các bước thực hiện | H5: Kết quả mong đợi | I5: Kết quả thực tế
A6: TC-01 | B6: Là Admin/Underwriter/Claim Oficer, tôi muốn truy cập màn hình Quản lý địa điểm/đối tượng BH để quản lý dữ liệu | C6: Quản lý địa điểm/đối tượng BH | D6: Truy cập màn hình | E6: Admin/Underwriter/Claim Oficer đã đăng nhập | F6: Verify truy cập màn hình danh sách | G6: 1. Đăng nhập bằng tài khoản Admin/Underwriter/Claim Oficer2. Vào menu Quản lý địa điểm/đối tượng BH | H6: Hiển thị màn hình danh sách “Quản lý địa điểm/đối tượng BH” | I6: Đạt
A7: TC-02 | B7: Là Admin/Underwriter/Claim Oficer, tôi muốn xem danh sách địa điểm/đối tượng BH | C7: Quản lý địa điểm/đối tượng BH | D7: Xem danh sách | E7: Đang ở màn hình danh sách | F7: Verify hiển thị danh sách và cột | G7: 1. Truy cập màn hình danh sách | H7: 1. Bảng hiển thị dữ liệu2. Có cột Địa điểm/đối tượng BH, P&L và cột thao tác (Sửa/Xóa) | I7: Đạt
A8: TC-03 | B8: Là Admin/Underwriter/Claim Oficer, tôi muốn kiểm tra nút thêm mới để tạo địa điểm/đối tượng BH | C8: Quản lý địa điểm/đối tượng BH | D8: Điều hướng tạo mới | E8: Đang ở màn hình danh sách | F8: Verify nút “+ Thêm địa điểm/đối tượng BH” hoạt động | G8: 1. Tại danh sách, bấm + Thêm địa điểm/đối tượng BH | H8: Điều hướng sang màn hình Thêm địa điểm/đối tượng BH | I8: Đạt
A9: TC-04 | B9: Là Admin/Underwriter/Claim Oficer, tôi muốn tìm kiếm theo từ khóa để lọc nhanh dữ liệu | C9: Quản lý địa điểm/đối tượng BH | D9: Tìm kiếm | E9: Có dữ liệu trong danh sách | F9: Verify tìm kiếm bằng ô “Tìm kiếm” trả đúng kết quả [Applied filtering common rules] | G9: 1. Nhập từ khóa khớp với 1 bản ghi (ví dụ 1 phần tên “SHERATON”)2. Quan sát danh sách sau khi nhập | H9: Danh sách được lọc đúng theo từ khóa; chỉ còn các bản ghi phù hợp | I9: Đạt
A10: TC-05 | B10: Là Admin/Underwriter/Claim Oficer, tôi muốn tìm kiếm không phân biệt HOA/thường để dễ dùng | C10: Quản lý địa điểm/đối tượng BH | D10: Tìm kiếm | E10: Có dữ liệu trong danh sách | F10: Verify tìm kiếm không phân biệt hoa/thường [Applied filtering common rules] | G10: 1. Nhập từ khóa dạng thường (vd: “sheraton”)2. Nhập từ khóa dạng HOA (vd: “SHERATON”) | H10: Kết quả 2 lần tìm kiếm giống nhau | I10: Đạt
A11: TC-06 | B11: Là Admin/Underwriter/Claim Oficer, tôi muốn sắp xếp theo thứ tự tăng dần cho Địa điểm/ Đối tượng BH | C11: Quản lý Công ty Bảo hiểm | D11: Xem danh sách | E11: Đang ở màn hình danh sách | F11: Sắp xếp tăng dần cho cột Địa điểm/ Đối tượng BH | G11: 1. Sắp xếp cột Địa điểm/ Đối tượng BH | H11: 1. Hiển thị đúng Địa điểm/ Đối tượng BH theo danh sách tăng dần | I11: Đạt
A12: TC-07 | B12: Là Admin/Underwriter/Claim Oficer, tôi muốn sắp xếp theo thứ tự giảm dần cho cột Địa điểm/ Đối tượng BH | C12: Quản lý Công ty Bảo hiểm | D12: Xem danh sách | E12: Đang ở màn hình danh sách | F12: Sắp xếp giảm dần cho cột Địa điểm/ Đối tượng BH | G12: 1. Sắp xếp cột Địa điểm/ Đối tượng BH | H12: 1. Hiển thị đúng Địa điểm/ Đối tượng BH theo danh sách giảm dần | I12: Đạt
